Traceback (most recent call last):
  File "/home/jovyan/envs/ooi-data-explorations/lib/python3.12/site-packages/jupyter_cache/executors/utils.py", line 58, in single_nb_execution
    executenb(
  File "/home/jovyan/envs/ooi-data-explorations/lib/python3.12/site-packages/nbclient/client.py", line 1319, in execute
    return NotebookClient(nb=nb, resources=resources, km=km, **kwargs).execute()
           ^^^^^^^^^^^^^^^^^^^^^^^^^^^^^^^^^^^^^^^^^^^^^^^^^^^^^^^^^^^^^^^^^^^^^
  File "/home/jovyan/envs/ooi-data-explorations/lib/python3.12/site-packages/jupyter_core/utils/__init__.py", line 165, in wrapped
    return loop.run_until_complete(inner)
           ^^^^^^^^^^^^^^^^^^^^^^^^^^^^^^
  File "/opt/conda/lib/python3.12/asyncio/base_events.py", line 687, in run_until_complete
    return future.result()
           ^^^^^^^^^^^^^^^
  File "/home/jovyan/envs/ooi-data-explorations/lib/python3.12/site-packages/nbclient/client.py", line 709, in async_execute
    await self.async_execute_cell(
  File "/home/jovyan/envs/ooi-data-explorations/lib/python3.12/site-packages/nbclient/client.py", line 1062, in async_execute_cell
    await self._check_raise_for_error(cell, cell_index, exec_reply)
  File "/home/jovyan/envs/ooi-data-explorations/lib/python3.12/site-packages/nbclient/client.py", line 918, in _check_raise_for_error
    raise CellExecutionError.from_cell_and_msg(cell, exec_reply_content)
nbclient.exceptions.CellExecutionError: An error occurred while executing the following cell:
------------------
# select the one stream for this data delivery method to use for the rest of this example
stream = streams[0]

# create lists of dictionaries with the available parameters and time ranges covered by each 
# dataset associated with the sensor
metadata = list_metadata(site, node, sensor)
parameters = metadata.pop('parameters')
time_ranges = metadata['times']

# print the parameter dictionaries for the parameters associated with this stream
for p in parameters:
    if p['stream'] == stream:
        pp.pprint(p)
------------------


[0;31m---------------------------------------------------------------------------[0m
[0;31mNameError[0m                                 Traceback (most recent call last)
Cell [0;32mIn[9], line 13[0m
[1;32m     11[0m [38;5;28;01mfor[39;00m p [38;5;129;01min[39;00m parameters:
[1;32m     12[0m     [38;5;28;01mif[39;00m p[[38;5;124m'[39m[38;5;124mstream[39m[38;5;124m'[39m] [38;5;241m==[39m stream:
[0;32m---> 13[0m         [43mpp[49m[38;5;241m.[39mpprint(p)

[0;31mNameError[0m: name 'pp' is not defined

